Workbook

Sheet Repartidores
A1: Repartidor | B1: Stack | C1: Switch | D1: Puerto | E1: Latiguillo | F1: VLAN | G1: Roseta | H1: Fecha | I1: Notas | J1: Shutdown
A2: 1 | B2: 1 | C2: 1 | D2: 1 | E2: 1001 | F2: 48 | G2: 1-001
A3: 1 | B3: 1 | C3: 1 | D3: 2 | E3: 1002 | F3: 48 | G3: 1-002
A4: 1 | B4: 1 | C4: 1 | D4: 3 | E4: 1003 | F4: 48 | G4: 1-003
A5: 1 | B5: 1 | C5: 1 | D5: 4 | E5: 1004 | F5: 48 | G5: 1-004
A6: 1 | B6: 1 | C6: 1 | D6: 5 | E6: 1005 | F6: 48 | G6: 1-006
A7: 1 | B7: 1 | C7: 1 | D7: 6 | E7: 1006 | F7: 48 | G7: 1-007
A8: 1 | B8: 1 | C8: 1 | D8: 7 | E8: 1007 | F8: 48 | G8: 1-011
A9: 1 | B9: 1 | C9: 1 | D9: 8 | E9: 1008 | F9: 48 | G9: 1-009
A10: 1 | B10: 1 | C10: 1 | D10: 9 | E10: 1009 | F10: 48 | G10: 1-010
A11: 1 | B11: 1 | C11: 1 | D11: 10 | E11: 1010 | F11: 66 | G11: 1-012
A12: 1 | B12: 1 | C12: 1 | D12: 11 | E12: 1011 | F12: 48 | G12: 1-013
A13: 1 | B13: 1 | C13: 1 | D13: 12 | E13: 1012 | F13: 48 | G13: 1-015
A14: 1 | B14: 1 | C14: 1 | D14: 13 | E14: 1013 | F14: 48 | G14: 1-016
... A16: 1 | B16: 1 | C16: 1 | D16: 15 | E16: 1015 | F16: 48 | G16: 1-020
A17: 1 | B17: 1 | C17: 1 | D17: 16 | E17: 1016 | F17: 48 | G17: 1-022
A18: 1 | B18: 1 | C18: 1 | D18: 17 | E18: 1017 | F18: 48 | G18: 1-024
A19: 1 | B19: 1 | C19: 1 | D19: 18 | E19: 1018 | F19: 44 | G19: 1-005
A20: 1 | B20: 1 | C20: 1 | D20: 19 | E20: 1019 | F20: 48 | G20: 1-032
A21: 1 | B21: 1 | C21: 1 | D21: 20 | E21: 1020 | F21: 44 | G21: 1-021
A22: 1 | B22: 1 | C22: 1 | D22: 21 | E22: 1021 | F22: 48 | G22: 1-152
A23: 1 | B23: 1 | C23: 1 | D23: 22 | E23: 1022 | F23: 48 | G23: 1-028
A24: 1 | B24: 1 | C24: 1 | D24: 23 | E24: 1023 | F24: 48 | G24: 1-008
A25: 1 | B25: 1 | C25: 1 | D25: 24 | E25: 1024 | F25: 48 | G25: 1-023
A26: 1 | B26: 1 | C26: 1 | D26: 25 | E26: 1025 | F26: 48 | G26: 1-029
A27: 1 | B27: 1 | C27: 1 | D27: 26 | E27: 1026 | F27: 48 | G27: 1-030
A28: 1 | B28: 1 | C28: 1 | D28: 27 | E28: 1027 | F28: 48 | G28: 1-031
A29: 1 | B29: 1 | C29: 1 | D29: 28 | E29: 1028 | F29: 44 | G29: 1-061
A30: 1 | B30: 1 | C30: 1 | D30: 29 | E30: 1029 | F30: 48 | G30: 1-034
A31: 1 | B31: 1 | C31: 1 | D31: 30 | E31: 360 | F31: 48 | G31: 1-036
A32: 1 | B32: 1 | C32: 1 | D32: 31 | E32: 1031 | F32: 48 | G32: 1-09V
A33: 1 | B33: 1 | C33: 1 | D33: 32 | E33: 1032 | F33: 48 | G33: 1-038
A34: 1 | B34: 1 | C34: 1 | D34: 33 | E34: 1033 | F34: 48 | G34: 1-039
A35: 1 | B35: 1 | C35: 1 | D35: 34 | E35: 1034 | F35: 48 | G35: 1-040
A36: 1 | B36: 1 | C36: 1 | D36: 35 | E36: 1035 | F36: 48 | G36: 1-041
A37: 1 | B37: 1 | C37: 1 | D37: 36 | E37: 1036 | F37: 48 | G37: 1-042
A38: 1 | B38: 1 | C38: 1 | D38: 37 | E38: 1037 | F38: 48 | G38: 1-046
A39: 1 | B39: 1 | C39: 1 | D39: 38 | E39: 1038 | F39: 44 | G39: 1-065
A40: 1 | B40: 1 | C40: 1 | D40: 39 | E40: 1039 | F40: 44 | G40: 1-055
A41: 1 | B41: 1 | C41: 1 | D41: 40 | E41: 1040 | F41: 48 | G41: 1-044
...

Sheet Rosetas
A1: Roseta | B1: Repartidor | C1: Panel | D1: Ubicación | E1: Dispositivo 1 | F1: Dato 1 | G1: Dispositivo 2 | H1: Dato 2
A2: 1-001 | B2: 1 | C2: 1
A3: 1-002 | B3: 1 | C3: 1
A4: 1-003 | B4: 1 | C4: 1
A5: 1-004 | B5: 1 | C5: 1
A6: 1-005 | B6: 1 | C6: 1
A7: 1-006 | B7: 1 | C7: 1
A8: 1-007 | B8: 1 | C8: 1
A9: 1-008 | B9: 1 | C9: 1
A10: 1-009 | B10: 1 | C10: 1
A11: 1-010 | B11: 1 | C11: 1
A12: 1-011 | B12: 1 | C12: 1
A13: 1-012 | B13: 1 | C13: 1
... A650: 2-283 | B650: 2 | C650: 12
A651: 2-284 | B651: 2 | C651: 12 | F651: agarces
A652: 2-285 | B652: 2 | C652: 12
A653: 2-286 | B653: 2 | C653: 12
A654: 2-287 | B654: 2 | C654: 12
A655: 2-288 | B655: 2 | C655: 12
A656: 2-289 | B656: 2 | C656: 13
A657: 2-290 | B657: 2 | C657: 13
A658: 2-291 | B658: 2 | C658: 13
A659: 2-292 | B659: 2 | C659: 13
A660: 2-293 | B660: 2 | C660: 13
A661: 2-294 | B661: 2 | C661: 13
A662: 2-295 | B662: 2 | C662: 13
A663: 2-296 | B663: 2 | C663: 13
... A1493: 5-002 | B1493: 5 | C1493: 1
A1494: 5-003 | B1494: 5 | C1494: 1 | D1494: Ampliación oficinas sur (despacho) | F1494: pbesman
A1495: 5-004 | B1495: 5 | C1495: 1
A1496: 5-005 | B1496: 5 | C1496: 1
A1497: 5-006 | B1497: 5 | C1497: 1
A1498: 5-007 | B1498: 5 | C1498: 1
A1499: 5-008 | B1499: 5 | C1499: 1 | D1499: Ampliación oficinas sur (despacho) | E1499: Pcs-lpt-237 | F1499: ipcalleja
A1500: 5-009 | B1500: 5 | C1500: 1
A1501: 5-010 | B1501: 5 | C1501: 1 | E1501: pcs-lpt-096 | F1501: dcmartinez
A1502: 5-011 | B1502: 5 | C1502: 1
A1503: 5-012 | B1503: 5 | C1503: 1
A1504: 5-013 | B1504: 5 | C1504: 1
A1505: 5-014 | B1505: 5 | C1505: 1
...

Sheet Parcheo de campo (Solo Lectura)
A1: Repartidor | B1: Stack | C1: Switch | D1: Puerto | E1: Latiguillo | F1: VLAN | G1: Panel | H1: Roseta | I1: Ubicación | J1: Dispositivo 1 | K1: Dato 1 | L1: Dispositivo 2 | M1: Dato 2
A2: =Repartidores!A2 -> 1 | B2: =Repartidores!B2 -> 1 | C2: =Repartidores!C2 -> 1 | D2: =Repartidores!D2 -> 1 | E2: =Repartidores!E2 -> 1001 | F2: =Repartidores!F2 -> 48 | G2: =VLOOKUP(H2,Rosetas!A:H,3,FALSE()) -> 1 | H2: 1-001
A3: =Repartidores!A3 -> 1 | B3: =Repartidores!B3 -> 1 | C3: =Repartidores!C3 -> 1 | D3: =Repartidores!D3 -> 2 | E3: =Repartidores!E3 -> 1002 | F3: =Repartidores!F3 -> 48 | G3: =VLOOKUP(H3,Rosetas!A:H,3,FALSE()) -> 1 | H3: 1-002
A4: =Repartidores!A4 -> 1 | B4: =Repartidores!B4 -> 1 | C4: =Repartidores!C4 -> 1 | D4: =Repartidores!D4 -> 3 | E4: =Repartidores!E4 -> 1003 | F4: =Repartidores!F4 -> 48 | G4: =VLOOKUP(H4,Rosetas!A:H,3,FALSE()) -> 1 | H4: 1-003
A5: =Repartidores!A5 -> 1 | B5: =Repartidores!B5 -> 1 | C5: =Repartidores!C5 -> 1 | D5: =Repartidores!D5 -> 4 | E5: =Repartidores!E5 -> 1004 | F5: =Repartidores!F5 -> 48 | G5: =VLOOKUP(H5,Rosetas!A:H,3,FALSE()) -> 1 | H5: 1-004
A6: =Repartidores!A6 -> 1 | B6: =Repartidores!B6 -> 1 | C6: =Repartidores!C6 -> 1 | D6: =Repartidores!D6 -> 5 | E6: =Repartidores!E6 -> 1005 | F6: =Repartidores!F6 -> 48 | G6: =VLOOKUP(H6,Rosetas!A:H,3,FALSE()) -> 1 | H6: 1-006
A7: =Repartidores!A7 -> 1 | B7: =Repartidores!B7 -> 1 | C7: =Repartidores!C7 -> 1 | D7: =Repartidores!D7 -> 6 | E7: =Repartidores!E7 -> 1006 | F7: =Repartidores!F7 -> 48 | G7: =VLOOKUP(H7,Rosetas!A:H,3,FALSE()) -> 1 | H7: 1-007
A8: =Repartidores!A8 -> 1 | B8: =Repartidores!B8 -> 1 | C8: =Repartidores!C8 -> 1 | D8: =Repartidores!D8 -> 7 | E8: =Repartidores!E8 -> 1007 | F8: =Repartidores!F8 -> 48 | G8: =VLOOKUP(H8,Rosetas!A:H,3,FALSE()) -> 1 | H8: 1-011
A9: =Repartidores!A9 -> 1 | B9: =Repartidores!B9 -> 1 | C9: =Repartidores!C9 -> 1 | D9: =Repartidores!D9 -> 8 | E9: =Repartidores!E9 -> 1008 | F9: =Repartidores!F9 -> 48 | G9: =VLOOKUP(H9,Rosetas!A:H,3,FALSE()) -> 1 | H9: 1-009
A10: =Repartidores!A10 -> 1 | B10: =Repartidores!B10 -> 1 | C10: =Repartidores!C10 -> 1 | D10: =Repartidores!D10 -> 9 | E10: =Repartidores!E10 -> 1009 | F10: =Repartidores!F10 -> 48 | G10: =VLOOKUP(H10,Rosetas!A:H,3,FALSE()) -> 1 | H10: 1-010
A11: =Repartidores!A11 -> 1 | B11: =Repartidores!B11 -> 1 | C11: =Repartidores!C11 -> 1 | D11: =Repartidores!D11 -> 10 | E11: =Repartidores!E11 -> 1010 | F11: =Repartidores!F11 -> 66 | G11: =VLOOKUP(H11,Rosetas!A:H,3,FALSE()) -> 1 | H11: 1-012
A12: =Repartidores!A12 -> 1 | B12: =Repartidores!B12 -> 1 | C12: =Repartidores!C12 -> 1 | D12: =Repartidores!D12 -> 11 | E12: =Repartidores!E12 -> 1011 | F12: =Repartidores!F12 -> 48 | G12: =VLOOKUP(H12,Rosetas!A:H,3,FALSE()) -> 1 | H12: 1-013
A13: =Repartidores!A13 -> 1 | B13: =Repartidores!B13 -> 1 | C13: =Repartidores!C13 -> 1 | D13: =Repartidores!D13 -> 12 | E13: =Repartidores!E13 -> 1012 | F13: =Repartidores!F13 -> 48 | G13: =VLOOKUP(H13,Rosetas!A:H,3,FALSE()) -> 1 | H13: 1-015
... A194: =Repartidores!A194 -> 1 | B194: =Repartidores!B194 -> 1 | C194: =Repartidores!C194 -> 5 | D194: =Repartidores!D194 -> 1 | E194: =Repartidores!E194 -> 289 | F194: =Repartidores!F194 -> 48 | G194: =VLOOKUP(H194,Rosetas!A:H,3,FALSE()) -> 7 | H194: 1-166
A195: =Repartidores!A195 -> 1 | B195: =Repartidores!B195 -> 1 | C195: =Repartidores!C195 -> 5 | D195: =Repartidores!D195 -> 2 | E195: =Repartidores!E195 -> - | F195: =Repartidores!F195 -> 48 | G195: =VLOOKUP(H195,Rosetas!A:H,3,FALSE()) -> -
A196: =Repartidores!A196 -> 1 | B196: =Repartidores!B196 -> 1 | C196: =Repartidores!C196 -> 5 | D196: =Repartidores!D196 -> 3 | E196: =Repartidores!E196 -> 608 | F196: =Repartidores!F196 -> 48 | G196: =VLOOKUP(H196,Rosetas!A:H,3,FALSE()) -> 4 | H196: 1-094
A197: =Repartidores!A197 -> 1 | B197: =Repartidores!B197 -> 1 | C197: =Repartidores!C197 -> 5 | D197: =Repartidores!D197 -> 4 | E197: =Repartidores!E197 -> - | F197: =Repartidores!F197 -> 48 | G197: =VLOOKUP(H197,Rosetas!A:H,3,FALSE()) -> -
A198: =Repartidores!A198 -> 1 | B198: =Repartidores!B198 -> 1 | C198: =Repartidores!C198 -> 5 | D198: =Repartidores!D198 -> 5 | E198: =Repartidores!E198 -> 521 | F198: =Repartidores!F198 -> 48 | G198: =VLOOKUP(H198,Rosetas!A:H,3,FALSE()) -> 2 | H198: 1-025
A199: =Repartidores!A199 -> 1 | B199: =Repartidores!B199 -> 1 | C199: =Repartidores!C199 -> 5 | D199: =Repartidores!D199 -> 6 | E199: =Repartidores!E199 -> - | F199: =Repartidores!F199 -> 48 | G199: =VLOOKUP(H199,Rosetas!A:H,3,FALSE()) -> -
A200: =Repartidores!A200 -> 1 | B200: =Repartidores!B200 -> 1 | C200: =Repartidores!C200 -> 5 | D200: =Repartidores!D200 -> 7 | E200: =Repartidores!E200 -> 796 | F200: =Repartidores!F200 -> 48 | G200: =VLOOKUP(H200,Rosetas!A:H,3,FALSE()) -> 2 | H200: 1-026
A201: =Repartidores!A201 -> 1 | B201: =Repartidores!B201 -> 1 | C201: =Repartidores!C201 -> 5 | D201: =Repartidores!D201 -> 8 | E201: =Repartidores!E201 -> - | F201: =Repartidores!F201 -> 48 | G201: =VLOOKUP(H201,Rosetas!A:H,3,FALSE()) -> -
A202: =Repartidores!A202 -> 1 | B202: =Repartidores!B202 -> 1 | C202: =Repartidores!C202 -> 5 | D202: =Repartidores!D202 -> 9 | E202: =Repartidores!E202 -> A102 | F202: =Repartidores!F202 -> 48 | G202: =VLOOKUP(H202,Rosetas!A:H,3,FALSE()) -> 4 | H202: 1-076
A203: =Repartidores!A203 -> 1 | B203: =Repartidores!B203 -> 1 | C203: =Repartidores!C203 -> 5 | D203: =Repartidores!D203 -> 10 | E203: =Repartidores!E203 -> - | F203: =Repartidores!F203 -> 48 | G203: =VLOOKUP(H203,Rosetas!A:H,3,FALSE()) -> -
A204: =Repartidores!A204 -> 1 | B204: =Repartidores!B204 -> 1 | C204: =Repartidores!C204 -> 5 | D204: =Repartidores!D204 -> 11 | E204: =Repartidores!E204 -> 106 | F204: =Repartidores!F204 -> 48 | G204: =VLOOKUP(H204,Rosetas!A:H,3,FALSE()) -> 8 | H204: 1-02V
A205: =Repartidores!A205 -> 1 | B205: =Repartidores!B205 -> 1 | C205: =Repartidores!C205 -> 5 | D205: =Repartidores!D205 -> 12 | E205: =Repartidores!E205 -> - | F205: =Repartidores!F205 -> 48 | G205: =VLOOKUP(H205,Rosetas!A:H,3,FALSE()) -> -
A206: =Repartidores!A206 -> 1 | B206: =Repartidores!B206 -> 1 | C206: =Repartidores!C206 -> 5 | D206: =Repartidores!D206 -> 13 | E206: =Repartidores!E206 -> A65 | F206: =Repartidores!F206 -> 48 | G206: =VLOOKUP(H206,Rosetas!A:H,3,FALSE()) -> 5 | H206: 1-097
A207: =Repartidores!A207 -> 1 | B207: =Repartidores!B207 -> 1 | C207: =Repartidores!C207 -> 5 | D207: =Repartidores!D207 -> 14 | E207: =Repartidores!E207 -> - | F207: =Repartidores!F207 -> 48 | G207: =VLOOKUP(H207,Rosetas!A:H,3,FALSE()) -> -
A208: =Repartidores!A208 -> 1 | B208: =Repartidores!B208 -> 1 | C208: =Repartidores!C208 -> 5 | D208: =Repartidores!D208 -> 15 | E208: =Repartidores!E208 -> A100 | F208: =Repartidores!F208 -> 48 | G208: =VLOOKUP(H208,Rosetas!A:H,3,FALSE()) -> 2 | H208: 1-037
A209: =Repartidores!A209 -> 1 | B209: =Repartidores!B209 -> 1 | C209: =Repartidores!C209 -> 5 | D209: =Repartidores!D209 -> 16 | E209: =Repartidores!E209 -> - | F209: =Repartidores!F209 -> 48 | G209: =VLOOKUP(H209,Rosetas!A:H,3,FALSE()) -> -
A210: =Repartidores!A210 -> 1 | B210: =Repartidores!B210 -> 1 | C210: =Repartidores!C210 -> 5 | D210: =Repartidores!D210 -> 17 | E210: =Repartidores!E210 -> 625 | F210: =Repartidores!F210 -> 66 | G210: =VLOOKUP(H210,Rosetas!A:H,3,FALSE()) -> n/a | H210: R4-9
A211: =Repartidores!A211 -> 1 | B211: =Repartidores!B211 -> 1 | C211: =Repartidores!C211 -> 5 | D211: =Repartidores!D211 -> 18 | E211: =Repartidores!E211 -> - | F211: =Repartidores!F211 -> 48 | G211: =VLOOKUP(H211,Rosetas!A:H,3,FALSE()) -> -
A212: =Repartidores!A212 -> 1 | B212: =Repartidores!B212 -> 1 | C212: =Repartidores!C212 -> 5 | D212: =Repartidores!D212 -> 19 | E212: =Repartidores!E212 -> - | F212: =Repartidores!F212 -> 66 | G212: =VLOOKUP(H212,Rosetas!A:H,3,FALSE()) -> -
A213: =Repartidores!A213 -> 1 | B213: =Repartidores!B213 -> 1 | C213: =Repartidores!C213 -> 5 | D213: =Repartidores!D213 -> 20 | E213: =Repartidores!E213 -> - | F213: =Repartidores!F213 -> 48 | G213: =VLOOKUP(H213,Rosetas!A:H,3,FALSE()) -> -
A214: =Repartidores!A214 -> 1 | B214: =Repartidores!B214 -> 1 | C214: =Repartidores!C214 -> 5 | D214: =Repartidores!D214 -> 21 | E214: =Repartidores!E214 -> 1854 | F214: =Repartidores!F214 -> 66 | G214: =VLOOKUP(H214,Rosetas!A:H,3,FALSE()) -> 17 | H214: 1-346
A215: =Repartidores!A215 -> 1 | B215: =Repartidores!B215 -> 1 | C215: =Repartidores!C215 -> 5 | D215: =Repartidores!D215 -> 22 | E215: =Repartidores!E215 -> - | F215: =Repartidores!F215 -> 48 | G215: =VLOOKUP(H215,Rosetas!A:H,3,FALSE()) -> -
A216: =Repartidores!A216 -> 1 | B216: =Repartidores!B216 -> 1 | C216: =Repartidores!C216 -> 5 | D216: =Repartidores!D216 -> 23 | E216: =Repartidores!E216 -> 617 | F216: =Repartidores!F216 -> 44 | G216: =VLOOKUP(H216,Rosetas!A:H,3,FALSE()) -> 9 | H216: 1-191
A217: =Repartidores!A217 -> 1 | B217: =Repartidores!B217 -> 1 | C217: =Repartidores!C217 -> 5 | D217: =Repartidores!D217 -> 24 | E217: =Repartidores!E217 -> - | F217: =Repartidores!F217 -> 48 | G217: =VLOOKUP(H217,Rosetas!A:H,3,FALSE()) -> -
A218: =Repartidores!A218 -> 1 | B218: =Repartidores!B218 -> 1 | C218: =Repartidores!C218 -> 5 | D218: =Repartidores!D218 -> 25 | E218: =Repartidores!E218 -> 527 | F218: =Repartidores!F218 -> 48 | G218: =VLOOKUP(H218,Rosetas!A:H,3,FALSE()) -> 4 | H218: 1-091
A219: =Repartidores!A219 -> 1 | B219: =Repartidores!B219 -> 1 | C219: =Repartidores!C219 -> 5 | D219: =Repartidores!D219 -> 26 | E219: =Repartidores!E219 -> - | F219: =Repartidores!F219 -> 48 | G219: =VLOOKUP(H219,Rosetas!A:H,3,FALSE()) -> -
A220: =Repartidores!A220 -> 1 | B220: =Repartidores!B220 -> 1 | C220: =Repartidores!C220 -> 5 | D220: =Repartidores!D220 -> 27 | E220: =Repartidores!E220 -> A79 | F220: =Repartidores!F220 -> 48 | G220: =VLOOKUP(H220,Rosetas!A:H,3,FALSE()) -> 5 | H220: 1-117
...
